Workbook

Sheet README
B2: D2C Sales Performance & Competitive Pricing Dashboard
B3: An ETL + sales/CRM analytics project — raw multi-source data, cleaning logic, pipeline KPIs, and competitor benchmarking
B5: Purpose
B6: This workbook simulates a Direct-to-Consumer (D2C) sales operation across multiple regions and product lines. It demonstrates an end-to-end analytics workflow: extracting raw data from two separate sources (a CRM export and a competitor pricing feed), validating and cleaning that data, transforming it into pipeline and revenue KPIs, and presenting it through an executive dashboard — the same workflow described in Revenue Operations, Sales Analytics, and Product & Price Management roles.
B8: Sheet Guide
B9: 1. CRM_Raw — Unprocessed CRM export (Source 1). Intentionally contains real-world data quality issues: inconsistent region casing, missing sales rep values. This mirrors the validation step before any reporting can happen.
B10: 2. Pricing_Raw — Unprocessed competitor pricing feed (Source 2), covering list prices, ratings, and delivery times across 6 competitor brands and 6 product lines.
B11: 3. Data_Cleaning_Log — Documents every validation rule applied and how many records were affected (the ETL 'Transform' step).
B12: 4. CRM_Clean — Cleaned, standardized dataset used for all downstream analysis (formulas reference CRM_Raw directly, so updating raw data updates everything).
B13: 5. Pipeline_Analysis — Funnel, conversion, win-rate, and sales-cycle metrics by region, product line, and lead source.
B14: 6. Competitor_Benchmark — Price positioning vs. 6 competitors per product line, with over/under-pricing flags.
B15: 7. Executive_Dashboard — KPI summary and charts for a management/sales audience.
... B21: All deal and pricing data in this workbook is synthetic, generated for demonstration purposes. The structure, fields, and analysis approach are designed to mirror a real D2C sales/CRM environment (e.g. Pipedrive/HubSpot/Salesforce exports).

Sheet CRM_Raw
A1: Source 1: Raw CRM Export (Unprocessed)
A2: Contains known data quality issues (inconsistent region casing, missing rep names) — see Data_Cleaning_Log
A4: Deal ID | B4: Created Date | C4: Closed Date | D4: Region | E4: Product Line | F4: Lead Source | G4: Sales Rep | H4: Stage | I4: Deal Value (EUR) | J4: Discount % | K4: Sales Cycle (Days)
A5: D-10001 | B5: 2025-09-08 | C5: 2025-09-27 | D5: Southern Europe | E5: Smart Ovens | F5: Web-shop Organic | G5: J. Murphy | H5: Closed Won | I5: 948.63 | J5: 0.1 | K5: 19
A6: D-10002 | B6: 2025-08-27 | C6: 2025-09-03 | D6: Benelux | E6: Smart Ovens | F6: Web-shop Organic | G6: S. Andersson | H6: Closed Lost | I6: 769.64 | J6: 0.15 | K6: 7
A7: D-10003 | B7: 2026-04-05 | C7: 2026-04-26 | D7: Southern Europe | E7: Small Kitchen Appliances | F7: Social Media Ads | G7: S. Andersson | H7: Closed Lost | I7: 267.12 | J7: 0 | K7: 21
A8: D-10004 | B8: 2025-04-15 | C8: 2025-05-05 | D8: France | E8: Coffee Systems | F8: Web-shop Organic | G8: P. Rossi | H8: Closed Won | I8: 478.86 | J8: 0.1 | K8: 20
A9: D-10005 | B9: 2026-01-23 | C9: 2026-02-09 | D9: France | E9: Smart Ovens | F9: Affiliate Partner | G9: L. Dubois | H9: Closed Won | I9: 947.23 | J9: 0.1 | K9: 17
A10: D-10006 | B10: 2025-10-24 | D10: UK & Ireland | E10: Small Kitchen Appliances | F10: Web-shop Organic | G10: S. Andersson | H10: Qualified | I10: 135.03 | J10: 0.05
A11: D-10007 | B11: 2025-06-16 | C11: 2025-07-19 | D11: France | E11: Dishwashers | F11: Affiliate Partner | G11: P. Rossi | H11: Closed Won | I11: 672.74 | J11: 0.15 | K11: 33
A12: D-10008 | B12: 2025-09-08 | C12: 2025-09-11 | D12: Southern Europe | E12: Small Kitchen Appliances | F12: Web-shop Organic | G12: M. Hoffmann | H12: Closed Won | I12: 385.92 | J12: 0 | K12: 3
A13: D-10009 | B13: 2025-08-23 | D13: Southern Europe | E13: Cordless Vacuums | F13: Email Campaign | G13: A. Becker | H13: Proposal Sent | I13: 784.65 | J13: 0
A14: D-10010 | B14: 2025-08-06 | D14: DACH | E14: Coffee Systems | F14: Retail Referral | G14: P. Rossi | H14: Negotiation | I14: 1033.21 | J14: 0
A15: D-10011 | B15: 2026-03-15 | D15: France | E15: Coffee Systems | F15: Web-shop Organic | G15: J. Murphy | H15: Qualified | I15: 517.08 | J15: 0
A16: D-10012 | B16: 2025-04-23 | C16: 2025-06-01 | D16: Nordics | E16: Dishwashers | F16: Web-shop Organic | G16: A. Becker | H16: Closed Won | I16: 1328.42 | J16: 0.1 | K16: 39
A17: D-10013 | B17: 2025-09-15 | D17: DACH | E17: Dishwashers | F17: Paid Search | H17: Qualified | I17: 784.94 | J17: 0.15
A18: D-10014 | B18: 2025-12-15 | C18: 2025-12-26 | D18: Southern Europe | E18: Smart Ovens | F18: Affiliate Partner | G18: J. Murphy | H18: Closed Won | I18: 961.37 | J18: 0.1 | K18: 11
A19: D-10015 | B19: 2025-11-02 | D19: North America | E19: Coffee Systems | F19: Social Media Ads | G19: L. Dubois | H19: Proposal Sent | I19: 530.75 | J19: 0
A20: D-10016 | B20: 2025-11-28 | C20: 2025-12-22 | D20: France | E20: Coffee Systems | F20: Social Media Ads | G20: A. Becker | H20: Closed Lost | I20: 480.78 | J20: 0.2 | K20: 24
A21: D-10017 | B21: 2025-03-22 | C21: 2025-04-08 | D21: North America | E21: Cordless Vacuums | F21: Web-shop Organic | G21: S. Andersson | H21: Closed Won | I21: 388.45 | J21: 0 | K21: 17
A22: D-10018 | B22: 2025-09-29 | C22: 2025-10-20 | D22: Southern Europe | E22: Dishwashers | F22: Retail Referral | G22: M. Hoffmann | H22: Closed Lost | I22: 741.15 | J22: 0.1 | K22: 21
A23: D-10019 | B23: 2026-02-13 | D23: North America | E23: Small Kitchen Appliances | F23: Affiliate Partner | G23: J. Murphy | H23: Qualified | I23: 257.86 | J23: 0.1
A24: D-10020 | B24: 2025-12-13 | C24: 2025-12-22 | D24: Benelux | E24: Smart Ovens | F24: Web-shop Organic | G24: L. Dubois | H24: Closed Won | I24: 765.64 | J24: 0 | K24: 9
A25: D-10021 | B25: 2025-09-01 | C25: 2025-09-18 | D25: DACH | E25: Smart Ovens | F25: Retail Referral | G25: L. Dubois | H25: Closed Won | I25: 2593.56 | J25: 0 | K25: 17
A26: D-10022 | B26: 2026-04-30 | D26: Southern Europe | E26: Washing Machines | F26: Social Media Ads | G26: S. Andersson | H26: Proposal Sent | I26: 624.76 | J26: 0.15
A27: D-10023 | B27: 2025-02-25 | D27: Benelux | E27: Cordless Vacuums | F27: Paid Search | G27: T. Wagner | H27: Negotiation | I27: 407.94 | J27: 0
A28: D-10024 | B28: 2025-09-12 | C28: 2025-09-28 | D28: Benelux | E28: Small Kitchen Appliances | F28: Paid Search | G28: L. Dubois | H28: Closed Won | I28: 230.19 | J28: 0 | K28: 16
A29: D-10025 | B29: 2025-02-21 | D29: North America | E29: Smart Ovens | F29: Paid Search | G29: L. Dubois | H29: Negotiation | I29: 875.93 | J29: 0
A30: D-10026 | B30: 2026-05-08 | C30: 2026-05-27 | D30: North America | E30: Coffee Systems | F30: Web-shop Organic | G30: T. Wagner | H30: Closed Won | I30: 517.29 | J30: 0 | K30: 19
A31: D-10027 | B31: 2026-04-11 | C31: 2026-04-27 | D31: Benelux | E31: Smart Ovens | F31: Trade Show | G31: J. Murphy | H31: Closed Won | I31: 1852.25 | J31: 0 | K31: 16
A32: D-10028 | B32: 2025-03-04 | D32: UK & Ireland | E32: Cordless Vacuums | F32: Web-shop Organic | G32: A. Becker | H32: Negotiation | I32: 981.4 | J32: 0.05
A33: D-10029 | B33: 2025-07-10 | C33: 2025-07-17 | D33: Nordics | E33: Washing Machines | F33: Web-shop Organic | G33: L. Dubois | H33: Closed Won | I33: 605.08 | J33: 0.05 | K33: 7
A34: D-10030 | B34: 2025-03-25 | C34: 2025-04-05 | D34: DACH | E34: Washing Machines | F34: Web-shop Organic | G34: A. Becker | H34: Closed Lost | I34: 744.42 | J34: 0.15 | K34: 11
A35: D-10031 | B35: 2025-05-15 | D35: Southern Europe | E35: Cordless Vacuums | F35: Web-shop Organic | G35: K. Nilsson | H35: Negotiation | I35: 348.3 | J35: 0.2
A36: D-10032 | B36: 2025-03-17 | C36: 2025-04-01 | D36: DACH | E36: Smart Ovens | F36: Social Media Ads | G36: L. Dubois | H36: Closed Lost | I36: 868.75 | J36: 0 | K36: 15
A37: D-10033 | B37: 2026-03-25 | D37: DACH | E37: Coffee Systems | F37: Paid Search | G37: M. Hoffmann | H37: Proposal Sent | I37: 1666.46 | J37: 0.2
A38: D-10034 | B38: 2025-04-17 | D38: Southern Europe | E38: Washing Machines | F38: Web-shop Organic | G38: J. Murphy | H38: Qualified | I38: 615.74 | J38: 0
A39: D-10035 | B39: 2025-08-04 | D39: Southern Europe | E39: Washing Machines | F39: Web-shop Organic | G39: J. Murphy | H39: Negotiation | I39: 626.88 | J39: 0.1
A40: D-10036 | B40: 2025-04-05 | D40: Benelux | E40: Cordless Vacuums | F40: Retail Referral | G40: A. Becker | H40: Negotiation | I40: 394.44 | J40: 0
A41: D-10037 | B41: 2025-06-15 | D41: France | E41: Coffee Systems | F41: Affiliate Partner | G41: J. Murphy | H41: Negotiation | I41: 1072.62 | J41: 0.1
...

Sheet Pricing_Raw
A1: Source 2: Raw Competitor Pricing Feed (Unprocessed)
A2: List prices, ratings, and delivery times across 6 competitor brands and 6 product lines
A4: Product Line | B4: Competitor | C4: List Price (EUR) | D4: Online Rating (out of 5) | E4: Delivery Time (Days)
A5: Smart Ovens | B5: Bosch/Siemens (Own) | C5: 899 | D5: 3.6 | E5: 7
A6: Smart Ovens | B6: Miele | C6: 1035.02 | D6: 3.8 | E6: 4
A7: Smart Ovens | B7: AEG/Electrolux | C7: 1023.74 | D7: 4 | E7: 7
A8: Smart Ovens | B8: Philips | C8: 941.62 | D8: 4 | E8: 10
A9: Smart Ovens | B9: Beko | C9: 843.85 | D9: 4.3 | E9: 2
A10: Smart Ovens | B10: Samsung | C10: 1080.14 | D10: 3.8 | E10: 10
A11: Smart Ovens | B11: LG | C11: 969.83 | D11: 3.6 | E11: 10
A12: Coffee Systems | B12: Bosch/Siemens (Own) | C12: 549 | D12: 4.6 | E12: 3
A13: Coffee Systems | B13: Miele | C13: 616.53 | D13: 4.7 | E13: 2
A14: Coffee Systems | B14: AEG/Electrolux | C14: 672.51 | D14: 4.3 | E14: 4
A15: Coffee Systems | B15: Philips | C15: 621.41 | D15: 4.8 | E15: 3
A16: Coffee Systems | B16: Beko | C16: 576.14 | D16: 3.8 | E16: 3
... A46: Small Kitchen Appliances | B46: LG | C46: 159.67 | D46: 4.2 | E46: 7

Sheet Data_Cleaning_Log
B2: Data Cleaning & Validation Log
B3: Documents the Transform step: every validation rule applied to CRM_Raw before it became CRM_Clean
B5: Rule # | C5: Issue Found | D5: Validation Rule Applied | E5: Records Affected | F5: Resolution
B6: 1 | C6: Inconsistent region naming (e.g. 'FRANCE' vs 'France') | D6: Standardize text case using TRIM + PROPER-style matching against a master region list | E6: 10 records | F6: Standardized to title case in CRM_Clean
B7: 2 | C7: Missing Sales Rep value | D7: Flag any row where Sales Rep is blank; cannot be auto-filled (no reliable source), so flagged for manual follow-up | E7: 29 records | F7: Labeled 'Unassigned' in CRM_Clean, excluded from rep-level leaderboards
B8: 3 | C8: Blank Closed Date for open deals | D8: Expected for any deal not yet in Closed Won/Lost — validated this matches open pipeline stages, not a data error | E8: 322 records | F8: Left blank intentionally; used to identify open pipeline
B9: 4 | C9: Deal Value outliers | D9: Flagged any deal value > 3x the product line's median price as a potential data entry error for review | E9: 0 records flagged | F9: No action needed — all values within expected range
B10: 5 | C10: Duplicate Deal IDs | D10: Checked for duplicate primary keys across the full export | E10: 0 duplicates found | F10: No action needed
B12: Source of truth for region standardization (used by CRM_Clean formulas):
B13: Master Region List
B14: Southern Europe
B15: DACH
B16: North America
B17: Benelux
B18: UK & Ireland
B19: France
B20: Nordics

Sheet CRM_Clean
A1: Cleaned CRM Dataset (Live Formulas — updates automatically if CRM_Raw changes)
A2: Region standardized, missing reps labeled, net deal value calculated after discount
A4: Deal ID | B4: Created Date | C4: Closed Date | D4: Region (Clean) | E4: Product Line | F4: Lead Source | G4: Sales Rep (Clean) | H4: Stage | I4: Deal Value (EUR) | J4: Discount % | K4: Net Deal Value (EUR) | L4: Sales Cycle (Days) | M4: Is Closed Won
A5: =CRM_Raw!A5 -> D-10001 | B5: =CRM_Raw!B5 -> 2025-09-08 | C5: =CRM_Raw!C5 -> 2025-09-27 | D5: =IF(CRM_Raw!D5="DACH","DACH",IF(ISNUMBER(SEARCH("uk",CRM_Raw!D5)),"UK & Ireland",PROPER(CRM_Raw!D5))) -> Southern Europe | E5: =CRM_Raw!E5 -> Smart Ovens | F5: =CRM_Raw!F5 -> Web-shop Organic | G5: =IF(TRIM(CRM_Raw!G5)="","Unassigned",CRM_Raw!G5) -> J. Murphy | H5: =CRM_Raw!H5 -> Closed Won | I5: =CRM_Raw!I5 -> 948.63 | J5: =CRM_Raw!J5 -> 0.1 | K5: =I5*(1-J5) -> 853.767 | L5: =CRM_Raw!K5 -> 19 | M5: =IF(H5="Closed Won",1,0) -> 1
A6: =CRM_Raw!A6 -> D-10002 | B6: =CRM_Raw!B6 -> 2025-08-27 | C6: =CRM_Raw!C6 -> 2025-09-03 | D6: =IF(CRM_Raw!D6="DACH","DACH",IF(ISNUMBER(SEARCH("uk",CRM_Raw!D6)),"UK & Ireland",PROPER(CRM_Raw!D6))) -> Benelux | E6: =CRM_Raw!E6 -> Smart Ovens | F6: =CRM_Raw!F6 -> Web-shop Organic | G6: =IF(TRIM(CRM_Raw!G6)="","Unassigned",CRM_Raw!G6) -> S. Andersson | H6: =CRM_Raw!H6 -> Closed Lost | I6: =CRM_Raw!I6 -> 769.64 | J6: =CRM_Raw!J6 -> 0.15 | K6: =I6*(1-J6) -> 654.194 | L6: =CRM_Raw!K6 -> 7 | M6: =IF(H6="Closed Won",1,0) -> 0
A7: =CRM_Raw!A7 -> D-10003 | B7: =CRM_Raw!B7 -> 2026-04-05 | C7: =CRM_Raw!C7 -> 2026-04-26 | D7: =IF(CRM_Raw!D7="DACH","DACH",IF(ISNUMBER(SEARCH("uk",CRM_Raw!D7)),"UK & Ireland",PROPER(CRM_Raw!D7))) -> Southern Europe | E7: =CRM_Raw!E7 -> Small Kitchen Appliances | F7: =CRM_Raw!F7 -> Social Media Ads | G7: =IF(TRIM(CRM_Raw!G7)="","Unassigned",CRM_Raw!G7) -> S. Andersson | H7: =CRM_Raw!H7 -> Closed Lost | I7: =CRM_Raw!I7 -> 267.12 | J7: =CRM_Raw!J7 -> 0 | K7: =I7*(1-J7) -> 267.12 | L7: =CRM_Raw!K7 -> 21 | M7: =IF(H7="Closed Won",1,0) -> 0
A8: =CRM_Raw!A8 -> D-10004 | B8: =CRM_Raw!B8 -> 2025-04-15 | C8: =CRM_Raw!C8 -> 2025-05-05 | D8: =IF(CRM_Raw!D8="DACH","DACH",IF(ISNUMBER(SEARCH("uk",CRM_Raw!D8)),"UK & Ireland",PROPER(CRM_Raw!D8))) -> France | E8: =CRM_Raw!E8 -> Coffee Systems | F8: =CRM_Raw!F8 -> Web-shop Organic | G8: =IF(TRIM(CRM_Raw!G8)="","Unassigned",CRM_Raw!G8) -> P. Rossi | H8: =CRM_Raw!H8 -> Closed Won | I8: =CRM_Raw!I8 -> 478.86 | J8: =CRM_Raw!J8 -> 0.1 | K8: =I8*(1-J8) -> 430.974 | L8: =CRM_Raw!K8 -> 20 | M8: =IF(H8="Closed Won",1,0) -> 1
A9: =CRM_Raw!A9 -> D-10005 | B9: =CRM_Raw!B9 -> 2026-01-23 | C9: =CRM_Raw!C9 -> 2026-02-09 | D9: =IF(CRM_Raw!D9="DACH","DACH",IF(ISNUMBER(SEARCH("uk",CRM_Raw!D9)),"UK & Ireland",PROPER(CRM_Raw!D9))) -> France | E9: =CRM_Raw!E9 -> Smart Ovens | F9: =CRM_Raw!F9 -> Affiliate Partner | G9: =IF(TRIM(CRM_Raw!G9)="","Unassigned",CRM_Raw!G9) -> L. Dubois | H9: =CRM_Raw!H9 -> Closed Won | I9: =CRM_Raw!I9 -> 947.23 | J9: =CRM_Raw!J9 -> 0.1 | K9: =I9*(1-J9) -> 852.507 | L9: =CRM_Raw!K9 -> 17 | M9: =IF(H9="Closed Won",1,0) -> 1
A10: =CRM_Raw!A10 -> D-10006 | B10: =CRM_Raw!B10 -> 2025-10-24 | C10: =CRM_Raw!C10 -> 0 | D10: =IF(CRM_Raw!D10="DACH","DACH",IF(ISNUMBER(SEARCH("uk",CRM_Raw!D10)),"UK & Ireland",PROPER(CRM_Raw!D10))) -> UK & Ireland | E10: =CRM_Raw!E10 -> Small Kitchen Appliances | F10: =CRM_Raw!F10 -> Web-shop Organic | G10: =IF(TRIM(CRM_Raw!G10)="","Unassigned",CRM_Raw!G10) -> S. Andersson | H10: =CRM_Raw!H10 -> Qualified | I10: =CRM_Raw!I10 -> 135.03 | J10: =CRM_Raw!J10 -> 0.05 | K10: =I10*(1-J10) -> 128.2785 | L10: =CRM_Raw!K10 -> 0 | M10: =IF(H10="Closed Won",1,0) -> 0
A11: =CRM_Raw!A11 -> D-10007 | B11: =CRM_Raw!B11 -> 2025-06-16 | C11: =CRM_Raw!C11 -> 2025-07-19 | D11: =IF(CRM_Raw!D11="DACH","DACH",IF(ISNUMBER(SEARCH("uk",CRM_Raw!D11)),"UK & Ireland",PROPER(CRM_Raw!D11))) -> France | E11: =CRM_Raw!E11 -> Dishwashers | F11: =CRM_Raw!F11 -> Affiliate Partner | G11: =IF(TRIM(CRM_Raw!G11)="","Unassigned",CRM_Raw!G11) -> P. Rossi | H11: =CRM_Raw!H11 -> Closed Won | I11: =CRM_Raw!I11 -> 672.74 | J11: =CRM_Raw!J11 -> 0.15 | K11: =I11*(1-J11) -> 571.829 | L11: =CRM_Raw!K11 -> 33 | M11: =IF(H11="Closed Won",1,0) -> 1
A12: =CRM_Raw!A12 -> D-10008 | B12: =CRM_Raw!B12 -> 2025-09-08 | C12: =CRM_Raw!C12 -> 2025-09-11 | D12: =IF(CRM_Raw!D12="DACH","DACH",IF(ISNUMBER(SEARCH("uk",CRM_Raw!D12)),"UK & Ireland",PROPER(CRM_Raw!D12))) -> Southern Europe | E12: =CRM_Raw!E12 -> Small Kitchen Appliances | F12: =CRM_Raw!F12 -> Web-shop Organic | G12: =IF(TRIM(CRM_Raw!G12)="","Unassigned",CRM_Raw!G12) -> M. Hoffmann | H12: =CRM_Raw!H12 -> Closed Won | I12: =CRM_Raw!I12 -> 385.92 | J12: =CRM_Raw!J12 -> 0 | K12: =I12*(1-J12) -> 385.92 | L12: =CRM_Raw!K12 -> 3 | M12: =IF(H12="Closed Won",1,0) -> 1
A13: =CRM_Raw!A13 -> D-10009 | B13: =CRM_Raw!B13 -> 2025-08-23 | C13: =CRM_Raw!C13 -> 0 | D13: =IF(CRM_Raw!D13="DACH","DACH",IF(ISNUMBER(SEARCH("uk",CRM_Raw!D13)),"UK & Ireland",PROPER(CRM_Raw!D13))) -> Southern Europe | E13: =CRM_Raw!E13 -> Cordless Vacuums | F13: =CRM_Raw!F13 -> Email Campaign | G13: =IF(TRIM(CRM_Raw!G13)="","Unassigned",CRM_Raw!G13) -> A. Becker | H13: =CRM_Raw!H13 -> Proposal Sent | I13: =CRM_Raw!I13 -> 784.65 | J13: =CRM_Raw!J13 -> 0 | K13: =I13*(1-J13) -> 784.65 | L13: =CRM_Raw!K13 -> 0 | M13: =IF(H13="Closed Won",1,0) -> 0
A14: =CRM_Raw!A14 -> D-10010 | B14: =CRM_Raw!B14 -> 2025-08-06 | C14: =CRM_Raw!C14 -> 0 | D14: =IF(CRM_Raw!D14="DACH","DACH",IF(ISNUMBER(SEARCH("uk",CRM_Raw!D14)),"UK & Ireland",PROPER(CRM_Raw!D14))) -> DACH | E14: =CRM_Raw!E14 -> Coffee Systems | F14: =CRM_Raw!F14 -> Retail Referral | G14: =IF(TRIM(CRM_Raw!G14)="","Unassigned",CRM_Raw!G14) -> P. Rossi | H14: =CRM_Raw!H14 -> Negotiation | I14: =CRM_Raw!I14 -> 1033.21 | J14: =CRM_Raw!J14 -> 0 | K14: =I14*(1-J14) -> 1033.21 | L14: =CRM_Raw!K14 -> 0 | M14: =IF(H14="Closed Won",1,0) -> 0
A15: =CRM_Raw!A15 -> D-10011 | B15: =CRM_Raw!B15 -> 2026-03-15 | C15: =CRM_Raw!C15 -> 0 | D15: =IF(CRM_Raw!D15="DACH","DACH",IF(ISNUMBER(SEARCH("uk",CRM_Raw!D15)),"UK & Ireland",PROPER(CRM_Raw!D15))) -> France | E15: =CRM_Raw!E15 -> Coffee Systems | F15: =CRM_Raw!F15 -> Web-shop Organic | G15: =IF(TRIM(CRM_Raw!G15)="","Unassigned",CRM_Raw!G15) -> J. Murphy | H15: =CRM_Raw!H15 -> Qualified | I15: =CRM_Raw!I15 -> 517.08 | J15: =CRM_Raw!J15 -> 0 | K15: =I15*(1-J15) -> 517.08 | L15: =CRM_Raw!K15 -> 0 | M15: =IF(H15="Closed Won",1,0) -> 0
A16: =CRM_Raw!A16 -> D-10012 | B16: =CRM_Raw!B16 -> 2025-04-23 | C16: =CRM_Raw!C16 -> 2025-06-01 | D16: =IF(CRM_Raw!D16="DACH","DACH",IF(ISNUMBER(SEARCH("uk",CRM_Raw!D16)),"UK & Ireland",PROPER(CRM_Raw!D16))) -> Nordics | E16: =CRM_Raw!E16 -> Dishwashers | F16: =CRM_Raw!F16 -> Web-shop Organic | G16: =IF(TRIM(CRM_Raw!G16)="","Unassigned",CRM_Raw!G16) -> A. Becker | H16: =CRM_Raw!H16 -> Closed Won | I16: =CRM_Raw!I16 -> 1328.42 | J16: =CRM_Raw!J16 -> 0.1 | K16: =I16*(1-J16) -> 1195.578 | L16: =CRM_Raw!K16 -> 39 | M16: =IF(H16="Closed Won",1,0) -> 1
... A854: =CRM_Raw!A854 -> D-10850 | B854: =CRM_Raw!B854 -> 2025-01-09 | C854: =CRM_Raw!C854 -> 0 | D854: =IF(CRM_Raw!D854="DACH","DACH",IF(ISNUMBER(SEARCH("uk",CRM_Raw!D854)),"UK & Ireland",PROPER(CRM_Raw!D854))) -> France | E854: =CRM_Raw!E854 -> Small Kitchen Appliances | F854: =CRM_Raw!F854 -> Affiliate Partner | G854: =IF(TRIM(CRM_Raw!G854)="","Unassigned",CRM_Raw!G854) -> P. Rossi | H854: =CRM_Raw!H854 -> Proposal Sent | I854: =CRM_Raw!I854 -> 409.08 | J854: =CRM_Raw!J854 -> 0 | K854: =I854*(1-J854) -> 409.08 | L854: =CRM_Raw!K854 -> 0 | M854: =IF(H854="Closed Won",1,0) -> 0

Sheet Pipeline_Analysis
B2: Sales Pipeline & Conversion Analysis
B3: All figures calculated live from CRM_Clean using SUMIFS / COUNTIFS / AVERAGEIFS
B5: 1. Deal Funnel by Stage
B6: Stage | C6: # Deals | D6: Total Value (EUR) | E6: % of Total Deals
B7: Qualified | C7: =COUNTIF(CRM_Clean!H5:H854,B7) -> 105 | D7: =SUMIF(CRM_Clean!H5:H854,B7,CRM_Clean!I5:I854) -> 91315.38 | E7: =C7/SUM($C$7:$C$11) -> 0.12352941
B8: Proposal Sent | C8: =COUNTIF(CRM_Clean!H5:H854,B8) -> 118 | D8: =SUMIF(CRM_Clean!H5:H854,B8,CRM_Clean!I5:I854) -> 101526.97 | E8: =C8/SUM($C$7:$C$11) -> 0.13882353
B9: Negotiation | C9: =COUNTIF(CRM_Clean!H5:H854,B9) -> 107 | D9: =SUMIF(CRM_Clean!H5:H854,B9,CRM_Clean!I5:I854) -> 81115.14 | E9: =C9/SUM($C$7:$C$11) -> 0.12588235
B10: Closed Won | C10: =COUNTIF(CRM_Clean!H5:H854,B10) -> 303 | D10: =SUMIF(CRM_Clean!H5:H854,B10,CRM_Clean!I5:I854) -> 260514.16 | E10: =C10/SUM($C$7:$C$11) -> 0.35647059
B11: Closed Lost | C11: =COUNTIF(CRM_Clean!H5:H854,B11) -> 217 | D11: =SUMIF(CRM_Clean!H5:H854,B11,CRM_Clean!I5:I854) -> 174742.68 | E11: =C11/SUM($C$7:$C$11) -> 0.25529412
B12: Total | C12: =SUM(C7:C11) -> 850 | D12: =SUM(D7:D11) -> 709214.33
B15: 2. Win Rate & Sales Cycle by Region
B16: Region | C16: Total Deals | D16: Closed Won | E16: Closed Lost | F16: Win Rate % | G16: Avg Sales Cycle (Days, Closed only) | H16: Won Revenue (EUR)
B17: DACH | C17: =COUNTIF(CRM_Clean!D5:D854,B17) -> 129 | D17: =COUNTIFS(CRM_Clean!D5:D854,B17,CRM_Clean!H5:H854,"Closed Won") -> 42 | E17: =COUNTIFS(CRM_Clean!D5:D854,B17,CRM_Clean!H5:H854,"Closed Lost") -> 29 | F17: =IFERROR(D17/(D17+E17),0) -> 0.5915493 | G17: =IFERROR((AVERAGEIFS(CRM_Clean!L5:L854,CRM_Clean!D5:D854,B17,CRM_Clean!H5:H854,"Closed Won")*D17+AVERAGEIFS(CRM_Clean!L5:L854,CRM_Clean!D5:D854,B17,CRM_Clean!H5:H854,"Closed Lost")*E17)/(D17+E17),0) -> 18.535211 | H17: =SUMIFS(CRM_Clean!K5:K854,CRM_Clean!D5:D854,B17,CRM_Clean!H5:H854,"Closed Won") -> 38521.306
B18: UK & Ireland | C18: =COUNTIF(CRM_Clean!D5:D854,B18) -> 114 | D18: =COUNTIFS(CRM_Clean!D5:D854,B18,CRM_Clean!H5:H854,"Closed Won") -> 27 | E18: =COUNTIFS(CRM_Clean!D5:D854,B18,CRM_Clean!H5:H854,"Closed Lost") -> 38 | F18: =IFERROR(D18/(D18+E18),0) -> 0.41538462 | G18: =IFERROR((AVERAGEIFS(CRM_Clean!L5:L854,CRM_Clean!D5:D854,B18,CRM_Clean!H5:H854,"Closed Won")*D18+AVERAGEIFS(CRM_Clean!L5:L854,CRM_Clean!D5:D854,B18,CRM_Clean!H5:H854,"Closed Lost")*E18)/(D18+E18),0) -> 19.4 | H18: =SUMIFS(CRM_Clean!K5:K854,CRM_Clean!D5:D854,B18,CRM_Clean!H5:H854,"Closed Won") -> 22581.059
B19: France | C19: =COUNTIF(CRM_Clean!D5:D854,B19) -> 114 | D19: =COUNTIFS(CRM_Clean!D5:D854,B19,CRM_Clean!H5:H854,"Closed Won") -> 51 | E19: =COUNTIFS(CRM_Clean!D5:D854,B19,CRM_Clean!H5:H854,"Closed Lost") -> 26 | F19: =IFERROR(D19/(D19+E19),0) -> 0.66233766 | G19: =IFERROR((AVERAGEIFS(CRM_Clean!L5:L854,CRM_Clean!D5:D854,B19,CRM_Clean!H5:H854,"Closed Won")*D19+AVERAGEIFS(CRM_Clean!L5:L854,CRM_Clean!D5:D854,B19,CRM_Clean!H5:H854,"Closed Lost")*E19)/(D19+E19),0) -> 19.792208 | H19: =SUMIFS(CRM_Clean!K5:K854,CRM_Clean!D5:D854,B19,CRM_Clean!H5:H854,"Closed Won") -> 36830.394
B20: Benelux | C20: =COUNTIF(CRM_Clean!D5:D854,B20) -> 119 | D20: =COUNTIFS(CRM_Clean!D5:D854,B20,CRM_Clean!H5:H854,"Closed Won") -> 54 | E20: =COUNTIFS(CRM_Clean!D5:D854,B20,CRM_Clean!H5:H854,"Closed Lost") -> 30 | F20: =IFERROR(D20/(D20+E20),0) -> 0.64285714 | G20: =IFERROR((AVERAGEIFS(CRM_Clean!L5:L854,CRM_Clean!D5:D854,B20,CRM_Clean!H5:H854,"Closed Won")*D20+AVERAGEIFS(CRM_Clean!L5:L854,CRM_Clean!D5:D854,B20,CRM_Clean!H5:H854,"Closed Lost")*E20)/(D20+E20),0) -> 18.107143 | H20: =SUMIFS(CRM_Clean!K5:K854,CRM_Clean!D5:D854,B20,CRM_Clean!H5:H854,"Closed Won") -> 46696.532
B21: Nordics | C21: =COUNTIF(CRM_Clean!D5:D854,B21) -> 111 | D21: =COUNTIFS(CRM_Clean!D5:D854,B21,CRM_Clean!H5:H854,"Closed Won") -> 36 | E21: =COUNTIFS(CRM_Clean!D5:D854,B21,CRM_Clean!H5:H854,"Closed Lost") -> 33 | F21: =IFERROR(D21/(D21+E21),0) -> 0.52173913 | G21: =IFERROR((AVERAGEIFS(CRM_Clean!L5:L854,CRM_Clean!D5:D854,B21,CRM_Clean!H5:H854,"Closed Won")*D21+AVERAGEIFS(CRM_Clean!L5:L854,CRM_Clean!D5:D854,B21,CRM_Clean!H5:H854,"Closed Lost")*E21)/(D21+E21),0) -> 20.666667 | H21: =SUMIFS(CRM_Clean!K5:K854,CRM_Clean!D5:D854,B21,CRM_Clean!H5:H854,"Closed Won") -> 25512.847
B22: Southern Europe | C22: =COUNTIF(CRM_Clean!D5:D854,B22) -> 137 | D22: =COUNTIFS(CRM_Clean!D5:D854,B22,CRM_Clean!H5:H854,"Closed Won") -> 46 | E22: =COUNTIFS(CRM_Clean!D5:D854,B22,CRM_Clean!H5:H854,"Closed Lost") -> 43 | F22: =IFERROR(D22/(D22+E22),0) -> 0.51685393 | G22: =IFERROR((AVERAGEIFS(CRM_Clean!L5:L854,CRM_Clean!D5:D854,B22,CRM_Clean!H5:H854,"Closed Won")*D22+AVERAGEIFS(CRM_Clean!L5:L854,CRM_Clean!D5:D854,B22,CRM_Clean!H5:H854,"Closed Lost")*E22)/(D22+E22),0) -> 19.089888 | H22: =SUMIFS(CRM_Clean!K5:K854,CRM_Clean!D5:D854,B22,CRM_Clean!H5:H854,"Closed Won") -> 35770.857
B23: North America | C23: =COUNTIF(CRM_Clean!D5:D854,B23) -> 126 | D23: =COUNTIFS(CRM_Clean!D5:D854,B23,CRM_Clean!H5:H854,"Closed Won") -> 47 | E23: =COUNTIFS(CRM_Clean!D5:D854,B23,CRM_Clean!H5:H854,"Closed Lost") -> 18 | F23: =IFERROR(D23/(D23+E23),0) -> 0.72307692 | G23: =IFERROR((AVERAGEIFS(CRM_Clean!L5:L854,CRM_Clean!D5:D854,B23,CRM_Clean!H5:H854,"Closed Won")*D23+AVERAGEIFS(CRM_Clean!L5:L854,CRM_Clean!D5:D854,B23,CRM_Clean!H5:H854,"Closed Lost")*E23)/(D23+E23),0) -> 19.707692 | H23: =SUMIFS(CRM_Clean!K5:K854,CRM_Clean!D5:D854,B23,CRM_Clean!H5:H854,"Closed Won") -> 36247.984
B27: 3. Performance by Product Line
B28: Product Line | C28: Total Deals | D28: Closed Won | E28: Win Rate % | F28: Won Revenue (EUR) | G28: Avg Deal Size (EUR, Won)
B29: Smart Ovens | C29: =COUNTIF(CRM_Clean!E5:E854,B29) -> 132 | D29: =COUNTIFS(CRM_Clean!E5:E854,B29,CRM_Clean!H5:H854,"Closed Won") -> 49 | E29: =IFERROR(D29/C29,0) -> 0.37121212 | F29: =SUMIFS(CRM_Clean!K5:K854,CRM_Clean!E5:E854,B29,CRM_Clean!H5:H854,"Closed Won") -> 60064.364 | G29: =IFERROR(F29/D29,0) -> 1225.8033
B30: Coffee Systems | C30: =COUNTIF(CRM_Clean!E5:E854,B30) -> 132 | D30: =COUNTIFS(CRM_Clean!E5:E854,B30,CRM_Clean!H5:H854,"Closed Won") -> 46 | E30: =IFERROR(D30/C30,0) -> 0.34848485 | F30: =SUMIFS(CRM_Clean!K5:K854,CRM_Clean!E5:E854,B30,CRM_Clean!H5:H854,"Closed Won") -> 39451.22 | G30: =IFERROR(F30/D30,0) -> 857.63522
B31: Cordless Vacuums | C31: =COUNTIF(CRM_Clean!E5:E854,B31) -> 138 | D31: =COUNTIFS(CRM_Clean!E5:E854,B31,CRM_Clean!H5:H854,"Closed Won") -> 49 | E31: =IFERROR(D31/C31,0) -> 0.35507246 | F31: =SUMIFS(CRM_Clean!K5:K854,CRM_Clean!E5:E854,B31,CRM_Clean!H5:H854,"Closed Won") -> 27695.823 | G31: =IFERROR(F31/D31,0) -> 565.22088
B32: Dishwashers | C32: =COUNTIF(CRM_Clean!E5:E854,B32) -> 127 | D32: =COUNTIFS(CRM_Clean!E5:E854,B32,CRM_Clean!H5:H854,"Closed Won") -> 49 | E32: =IFERROR(D32/C32,0) -> 0.38582677 | F32: =SUMIFS(CRM_Clean!K5:K854,CRM_Clean!E5:E854,B32,CRM_Clean!H5:H854,"Closed Won") -> 56315.365 | G32: =IFERROR(F32/D32,0) -> 1149.2932
B33: Washing Machines | C33: =COUNTIF(CRM_Clean!E5:E854,B33) -> 148 | D33: =COUNTIFS(CRM_Clean!E5:E854,B33,CRM_Clean!H5:H854,"Closed Won") -> 45 | E33: =IFERROR(D33/C33,0) -> 0.30405405 | F33: =SUMIFS(CRM_Clean!K5:K854,CRM_Clean!E5:E854,B33,CRM_Clean!H5:H854,"Closed Won") -> 44683.378 | G33: =IFERROR(F33/D33,0) -> 992.96397
B34: Small Kitchen Appliances | C34: =COUNTIF(CRM_Clean!E5:E854,B34) -> 173 | D34: =COUNTIFS(CRM_Clean!E5:E854,B34,CRM_Clean!H5:H854,"Closed Won") -> 65 | E34: =IFERROR(D34/C34,0) -> 0.37572254 | F34: =SUMIFS(CRM_Clean!K5:K854,CRM_Clean!E5:E854,B34,CRM_Clean!H5:H854,"Closed Won") -> 13950.827 | G34: =IFERROR(F34/D34,0) -> 214.62812
B38: 4. Performance by Lead Source
B39: Lead Source | C39: Total Deals | D39: Closed Won | E39: Conversion Rate % | F39: Won Revenue (EUR)
B40: Web-shop Organic | C40: =COUNTIF(CRM_Clean!F5:F854,B40) -> 215 | D40: =COUNTIFS(CRM_Clean!F5:F854,B40,CRM_Clean!H5:H854,"Closed Won") -> 79 | E40: =IFERROR(D40/C40,0) -> 0.36744186 | F40: =SUMIFS(CRM_Clean!K5:K854,CRM_Clean!F5:F854,B40,CRM_Clean!H5:H854,"Closed Won") -> 63814.352
B41: Paid Search | C41: =COUNTIF(CRM_Clean!F5:F854,B41) -> 171 | D41: =COUNTIFS(CRM_Clean!F5:F854,B41,CRM_Clean!H5:H854,"Closed Won") -> 68 | E41: =IFERROR(D41/C41,0) -> 0.39766082 | F41: =SUMIFS(CRM_Clean!K5:K854,CRM_Clean!F5:F854,B41,CRM_Clean!H5:H854,"Closed Won") -> 54899.119
B42: Social Media Ads | C42: =COUNTIF(CRM_Clean!F5:F854,B42) -> 150 | D42: =COUNTIFS(CRM_Clean!F5:F854,B42,CRM_Clean!H5:H854,"Closed Won") -> 49 | E42: =IFERROR(D42/C42,0) -> 0.32666667 | F42: =SUMIFS(CRM_Clean!K5:K854,CRM_Clean!F5:F854,B42,CRM_Clean!H5:H854,"Closed Won") -> 38005.048
B43: Affiliate Partner | C43: =COUNTIF(CRM_Clean!F5:F854,B43) -> 109 | D43: =COUNTIFS(CRM_Clean!F5:F854,B43,CRM_Clean!H5:H854,"Closed Won") -> 37 | E43: =IFERROR(D43/C43,0) -> 0.33944954 | F43: =SUMIFS(CRM_Clean!K5:K854,CRM_Clean!F5:F854,B43,CRM_Clean!H5:H854,"Closed Won") -> 30881.943
B44: Email Campaign | C44: =COUNTIF(CRM_Clean!F5:F854,B44) -> 80 | D44: =COUNTIFS(CRM_Clean!F5:F854,B44,CRM_Clean!H5:H854,"Closed Won") -> 24 | E44: =IFERROR(D44/C44,0) -> 0.3 | F44: =SUMIFS(CRM_Clean!K5:K854,CRM_Clean!F5:F854,B44,CRM_Clean!H5:H854,"Closed Won") -> 20676.423
B45: Retail Referral | C45: =COUNTIF(CRM_Clean!F5:F854,B45) -> 88 | D45: =COUNTIFS(CRM_Clean!F5:F854,B45,CRM_Clean!H5:H854,"Closed Won") -> 32 | E45: =IFERROR(D45/C45,0) -> 0.36363636 | F45: =SUMIFS(CRM_Clean!K5:K854,CRM_Clean!F5:F854,B45,CRM_Clean!H5:H854,"Closed Won") -> 20575.74
B46: Trade Show | C46: =COUNTIF(CRM_Clean!F5:F854,B46) -> 37 | D46: =COUNTIFS(CRM_Clean!F5:F854,B46,CRM_Clean!H5:H854,"Closed Won") -> 14 | E46: =IFERROR(D46/C46,0) -> 0.37837838 | F46: =SUMIFS(CRM_Clean!K5:K854,CRM_Clean!F5:F854,B46,CRM_Clean!H5:H854,"Closed Won") -> 13308.353
B50: 5. Sales Rep Leaderboard
B51: Sales Rep | C51: Total Deals | D51: Closed Won | E51: Win Rate % | F51: Won Revenue (EUR)
B52: A. Becker | C52: =COUNTIF(CRM_Clean!G5:G854,B52) -> 106 | D52: =COUNTIFS(CRM_Clean!G5:G854,B52,CRM_Clean!H5:H854,"Closed Won") -> 35 | E52: =IFERROR(D52/C52,0) -> 0.33018868 | F52: =SUMIFS(CRM_Clean!K5:K854,CRM_Clean!G5:G854,B52,CRM_Clean!H5:H854,"Closed Won") -> 28900.269
B53: L. Dubois | C53: =COUNTIF(CRM_Clean!G5:G854,B53) -> 105 | D53: =COUNTIFS(CRM_Clean!G5:G854,B53,CRM_Clean!H5:H854,"Closed Won") -> 42 | E53: =IFERROR(D53/C53,0) -> 0.4 | F53: =SUMIFS(CRM_Clean!K5:K854,CRM_Clean!G5:G854,B53,CRM_Clean!H5:H854,"Closed Won") -> 31703.243
...

Sheet Competitor_Benchmark
B2: Competitive Pricing Benchmark | N2: Helper: Smart Ovens | O2: Helper: Coffee Systems | P2: Helper: Cordless Vacuums | Q2: Helper: Dishwashers | R2: Helper: Washing Machines | S2: Helper: Small Kitchen Appliances
B3: Own (Bosch/Siemens) list price vs. 6 competitors per product line, pulled live from Pricing_Raw | N3: =IF(AND(Pricing_Raw!A5="Smart Ovens",Pricing_Raw!B5<>"Bosch/Siemens (Own)"),Pricing_Raw!C5,"") | O3: =IF(AND(Pricing_Raw!A5="Coffee Systems",Pricing_Raw!B5<>"Bosch/Siemens (Own)"),Pricing_Raw!C5,"") | P3: =IF(AND(Pricing_Raw!A5="Cordless Vacuums",Pricing_Raw!B5<>"Bosch/Siemens (Own)"),Pricing_Raw!C5,"") | Q3: =IF(AND(Pricing_Raw!A5="Dishwashers",Pricing_Raw!B5<>"Bosch/Siemens (Own)"),Pricing_Raw!C5,"") | R3: =IF(AND(Pricing_Raw!A5="Washing Machines",Pricing_Raw!B5<>"Bosch/Siemens (Own)"),Pricing_Raw!C5,"") | S3: =IF(AND(Pricing_Raw!A5="Small Kitchen Appliances",Pricing_Raw!B5<>"Bosch/Siemens (Own)"),Pricing_Raw!C5,"")
N4: =IF(AND(Pricing_Raw!A6="Smart Ovens",Pricing_Raw!B6<>"Bosch/Siemens (Own)"),Pricing_Raw!C6,"") -> 1035.02 | O4: =IF(AND(Pricing_Raw!A6="Coffee Systems",Pricing_Raw!B6<>"Bosch/Siemens (Own)"),Pricing_Raw!C6,"") | P4: =IF(AND(Pricing_Raw!A6="Cordless Vacuums",Pricing_Raw!B6<>"Bosch/Siemens (Own)"),Pricing_Raw!C6,"") | Q4: =IF(AND(Pricing_Raw!A6="Dishwashers",Pricing_Raw!B6<>"Bosch/Siemens (Own)"),Pricing_Raw!C6,"") | R4: =IF(AND(Pricing_Raw!A6="Washing Machines",Pricing_Raw!B6<>"Bosch/Siemens (Own)"),Pricing_Raw!C6,"") | S4: =IF(AND(Pricing_Raw!A6="Small Kitchen Appliances",Pricing_Raw!B6<>"Bosch/Siemens (Own)"),Pricing_Raw!C6,"")
B5: 1. Price Positioning Summary by Product Line | N5: =IF(AND(Pricing_Raw!A7="Smart Ovens",Pricing_Raw!B7<>"Bosch/Siemens (Own)"),Pricing_Raw!C7,"") -> 1023.74 | O5: =IF(AND(Pricing_Raw!A7="Coffee Systems",Pricing_Raw!B7<>"Bosch/Siemens (Own)"),Pricing_Raw!C7,"") | P5: =IF(AND(Pricing_Raw!A7="Cordless Vacuums",Pricing_Raw!B7<>"Bosch/Siemens (Own)"),Pricing_Raw!C7,"") | Q5: =IF(AND(Pricing_Raw!A7="Dishwashers",Pricing_Raw!B7<>"Bosch/Siemens (Own)"),Pricing_Raw!C7,"") | R5: =IF(AND(Pricing_Raw!A7="Washing Machines",Pricing_Raw!B7<>"Bosch/Siemens (Own)"),Pricing_Raw!C7,"") | S5: =IF(AND(Pricing_Raw!A7="Small Kitchen Appliances",Pricing_Raw!B7<>"Bosch/Siemens (Own)"),Pricing_Raw!C7,"")
B6: Product Line | C6: Own Price (EUR) | D6: Avg Competitor Price (EUR) | E6: Min Competitor Price (EUR) | F6: Max Competitor Price (EUR) | G6: Price Gap vs Avg (%) | H6: Positioning | N6: =IF(AND(Pricing_Raw!A8="Smart Ovens",Pricing_Raw!B8<>"Bosch/Siemens (Own)"),Pricing_Raw!C8,"") -> 941.62 | O6: =IF(AND(Pricing_Raw!A8="Coffee Systems",Pricing_Raw!B8<>"Bosch/Siemens (Own)"),Pricing_Raw!C8,"") | P6: =IF(AND(Pricing_Raw!A8="Cordless Vacuums",Pricing_Raw!B8<>"Bosch/Siemens (Own)"),Pricing_Raw!C8,"") | Q6: =IF(AND(Pricing_Raw!A8="Dishwashers",Pricing_Raw!B8<>"Bosch/Siemens (Own)"),Pricing_Raw!C8,"") | R6: =IF(AND(Pricing_Raw!A8="Washing Machines",Pricing_Raw!B8<>"Bosch/Siemens (Own)"),Pricing_Raw!C8,"") | S6: =IF(AND(Pricing_Raw!A8="Small Kitchen Appliances",Pricing_Raw!B8<>"Bosch/Siemens (Own)"),Pricing_Raw!C8,"")
B7: Smart Ovens | C7: =SUMIFS(Pricing_Raw!C5:C46,Pricing_Raw!A5:A46,B7,Pricing_Raw!B5:B46,"Bosch/Siemens (Own)") -> 899 | D7: =AVERAGEIFS(Pricing_Raw!C5:C46,Pricing_Raw!A5:A46,B7,Pricing_Raw!B5:B46,"<>Bosch/Siemens (Own)") -> 982.36667 | E7: =MIN(N3:N44) -> 843.85 | F7: =MAX(N3:N44) -> 1080.14 | G7: =(C7-D7)/D7 -> -0.084863086 | H7: =IF(G7<-0.05,"Underpriced vs market",IF(G7>0.05,"Premium positioning","At market")) -> Underpriced vs market | N7: =IF(AND(Pricing_Raw!A9="Smart Ovens",Pricing_Raw!B9<>"Bosch/Siemens (Own)"),Pricing_Raw!C9,"") -> 843.85 | O7: =IF(AND(Pricing_Raw!A9="Coffee Systems",Pricing_Raw!B9<>"Bosch/Siemens (Own)"),Pricing_Raw!C9,"") | P7: =IF(AND(Pricing_Raw!A9="Cordless Vacuums",Pricing_Raw!B9<>"Bosch/Siemens (Own)"),Pricing_Raw!C9,"") | Q7: =IF(AND(Pricing_Raw!A9="Dishwashers",Pricing_Raw!B9<>"Bosch/Siemens (Own)"),Pricing_Raw!C9,"") | R7: =IF(AND(Pricing_Raw!A9="Washing Machines",Pricing_Raw!B9<>"Bosch/Siemens (Own)"),Pricing_Raw!C9,"") | S7: =IF(AND(Pricing_Raw!A9="Small Kitchen Appliances",Pricing_Raw!B9<>"Bosch/Siemens (Own)"),Pricing_Raw!C9,"")
B8: Coffee Systems | C8: =SUMIFS(Pricing_Raw!C5:C46,Pricing_Raw!A5:A46,B8,Pricing_Raw!B5:B46,"Bosch/Siemens (Own)") -> 549 | D8: =AVERAGEIFS(Pricing_Raw!C5:C46,Pricing_Raw!A5:A46,B8,Pricing_Raw!B5:B46,"<>Bosch/Siemens (Own)") -> 607.115 | E8: =MIN(O3:O44) -> 495.44 | F8: =MAX(O3:O44) -> 672.51 | G8: =(C8-D8)/D8 -> -0.095723216 | H8: =IF(G8<-0.05,"Underpriced vs market",IF(G8>0.05,"Premium positioning","At market")) -> Underpriced vs market | N8: =IF(AND(Pricing_Raw!A10="Smart Ovens",Pricing_Raw!B10<>"Bosch/Siemens (Own)"),Pricing_Raw!C10,"") -> 1080.14 | O8: =IF(AND(Pricing_Raw!A10="Coffee Systems",Pricing_Raw!B10<>"Bosch/Siemens (Own)"),Pricing_Raw!C10,"") | P8: =IF(AND(Pricing_Raw!A10="Cordless Vacuums",Pricing_Raw!B10<>"Bosch/Siemens (Own)"),Pricing_Raw!C10,"") | Q8: =IF(AND(Pricing_Raw!A10="Dishwashers",Pricing_Raw!B10<>"Bosch/Siemens (Own)"),Pricing_Raw!C10,"") | R8: =IF(AND(Pricing_Raw!A10="Washing Machines",Pricing_Raw!B10<>"Bosch/Siemens (Own)"),Pricing_Raw!C10,"") | S8: =IF(AND(Pricing_Raw!A10="Small Kitchen Appliances",Pricing_Raw!B10<>"Bosch/Siemens (Own)"),Pricing_Raw!C10,"")
B9: Cordless Vacuums | C9: =SUMIFS(Pricing_Raw!C5:C46,Pricing_Raw!A5:A46,B9,Pricing_Raw!B5:B46,"Bosch/Siemens (Own)") -> 379 | D9: =AVERAGEIFS(Pricing_Raw!C5:C46,Pricing_Raw!A5:A46,B9,Pricing_Raw!B5:B46,"<>Bosch/Siemens (Own)") -> 396.33333 | E9: =MIN(P3:P44) -> 321.81 | F9: =MAX(P3:P44) -> 466.55 | G9: =(C9-D9)/D9 -> -0.04373423 | H9: =IF(G9<-0.05,"Underpriced vs market",IF(G9>0.05,"Premium positioning","At market")) -> At market | N9: =IF(AND(Pricing_Raw!A11="Smart Ovens",Pricing_Raw!B11<>"Bosch/Siemens (Own)"),Pricing_Raw!C11,"") -> 969.83 | O9: =IF(AND(Pricing_Raw!A11="Coffee Systems",Pricing_Raw!B11<>"Bosch/Siemens (Own)"),Pricing_Raw!C11,"") | P9: =IF(AND(Pricing_Raw!A11="Cordless Vacuums",Pricing_Raw!B11<>"Bosch/Siemens (Own)"),Pricing_Raw!C11,"") | Q9: =IF(AND(Pricing_Raw!A11="Dishwashers",Pricing_Raw!B11<>"Bosch/Siemens (Own)"),Pricing_Raw!C11,"") | R9: =IF(AND(Pricing_Raw!A11="Washing Machines",Pricing_Raw!B11<>"Bosch/Siemens (Own)"),Pricing_Raw!C11,"") | S9: =IF(AND(Pricing_Raw!A11="Small Kitchen Appliances",Pricing_Raw!B11<>"Bosch/Siemens (Own)"),Pricing_Raw!C11,"")
B10: Dishwashers | C10: =SUMIFS(Pricing_Raw!C5:C46,Pricing_Raw!A5:A46,B10,Pricing_Raw!B5:B46,"Bosch/Siemens (Own)") -> 749 | D10: =AVERAGEIFS(Pricing_Raw!C5:C46,Pricing_Raw!A5:A46,B10,Pricing_Raw!B5:B46,"<>Bosch/Siemens (Own)") -> 753.055 | E10: =MIN(Q3:Q44) -> 617.03 | F10: =MAX(Q3:Q44) -> 927.08 | G10: =(C10-D10)/D10 -> -0.0053847329 | H10: =IF(G10<-0.05,"Underpriced vs market",IF(G10>0.05,"Premium positioning","At market")) -> At market | N10: =IF(AND(Pricing_Raw!A12="Smart Ovens",Pricing_Raw!B12<>"Bosch/Siemens (Own)"),Pricing_Raw!C12,"") | O10: =IF(AND(Pricing_Raw!A12="Coffee Systems",Pricing_Raw!B12<>"Bosch/Siemens (Own)"),Pricing_Raw!C12,"") | P10: =IF(AND(Pricing_Raw!A12="Cordless Vacuums",Pricing_Raw!B12<>"Bosch/Siemens (Own)"),Pricing_Raw!C12,"") | Q10: =IF(AND(Pricing_Raw!A12="Dishwashers",Pricing_Raw!B12<>"Bosch/Siemens (Own)"),Pricing_Raw!C12,"") | R10: =IF(AND(Pricing_Raw!A12="Washing Machines",Pricing_Raw!B12<>"Bosch/Siemens (Own)"),Pricing_Raw!C12,"") | S10: =IF(AND(Pricing_Raw!A12="Small Kitchen Appliances",Pricing_Raw!B12<>"Bosch/Siemens (Own)"),Pricing_Raw!C12,"")
B11: Washing Machines | C11: =SUMIFS(Pricing_Raw!C5:C46,Pricing_Raw!A5:A46,B11,Pricing_Raw!B5:B46,"Bosch/Siemens (Own)") -> 699 | D11: =AVERAGEIFS(Pricing_Raw!C5:C46,Pricing_Raw!A5:A46,B11,Pricing_Raw!B5:B46,"<>Bosch/Siemens (Own)") -> 716.63 | E11: =MIN(R3:R44) -> 624.61 | F11: =MAX(R3:R44) -> 851.88 | G11: =(C11-D11)/D11 -> -0.024601259 | H11: =IF(G11<-0.05,"Underpriced vs market",IF(G11>0.05,"Premium positioning","At market")) -> At market | N11: =IF(AND(Pricing_Raw!A13="Smart Ovens",Pricing_Raw!B13<>"Bosch/Siemens (Own)"),Pricing_Raw!C13,"") | O11: =IF(AND(Pricing_Raw!A13="Coffee Systems",Pricing_Raw!B13<>"Bosch/Siemens (Own)"),Pricing_Raw!C13,"") -> 616.53 | P11: =IF(AND(Pricing_Raw!A13="Cordless Vacuums",Pricing_Raw!B13<>"Bosch/Siemens (Own)"),Pricing_Raw!C13,"") | Q11: =IF(AND(Pricing_Raw!A13="Dishwashers",Pricing_Raw!B13<>"Bosch/Siemens (Own)"),Pricing_Raw!C13,"") | R11: =IF(AND(Pricing_Raw!A13="Washing Machines",Pricing_Raw!B13<>"Bosch/Siemens (Own)"),Pricing_Raw!C13,"") | S11: =IF(AND(Pricing_Raw!A13="Small Kitchen Appliances",Pricing_Raw!B13<>"Bosch/Siemens (Own)"),Pricing_Raw!C13,"")
B12: Small Kitchen Appliances | C12: =SUMIFS(Pricing_Raw!C5:C46,Pricing_Raw!A5:A46,B12,Pricing_Raw!B5:B46,"Bosch/Siemens (Own)") -> 129 | D12: =AVERAGEIFS(Pricing_Raw!C5:C46,Pricing_Raw!A5:A46,B12,Pricing_Raw!B5:B46,"<>Bosch/Siemens (Own)") -> 137.22667 | E12: =MIN(S3:S44) -> 120.43 | F12: =MAX(S3:S44) -> 159.67 | G12: =(C12-D12)/D12 -> -0.059949475 | H12: =IF(G12<-0.05,"Underpriced vs market",IF(G12>0.05,"Premium positioning","At market")) -> Underpriced vs market | N12: =IF(AND(Pricing_Raw!A14="Smart Ovens",Pricing_Raw!B14<>"Bosch/Siemens (Own)"),Pricing_Raw!C14,"") | O12: =IF(AND(Pricing_Raw!A14="Coffee Systems",Pricing_Raw!B14<>"Bosch/Siemens (Own)"),Pricing_Raw!C14,"") -> 672.51 | P12: =IF(AND(Pricing_Raw!A14="Cordless Vacuums",Pricing_Raw!B14<>"Bosch/Siemens (Own)"),Pricing_Raw!C14,"") | Q12: =IF(AND(Pricing_Raw!A14="Dishwashers",Pricing_Raw!B14<>"Bosch/Siemens (Own)"),Pricing_Raw!C14,"") | R12: =IF(AND(Pricing_Raw!A14="Washing Machines",Pricing_Raw!B14<>"Bosch/Siemens (Own)"),Pricing_Raw!C14,"") | S12: =IF(AND(Pricing_Raw!A14="Small Kitchen Appliances",Pricing_Raw!B14<>"Bosch/Siemens (Own)"),Pricing_Raw!C14,"")
N13: =IF(AND(Pricing_Raw!A15="Smart Ovens",Pricing_Raw!B15<>"Bosch/Siemens (Own)"),Pricing_Raw!C15,"") | O13: =IF(AND(Pricing_Raw!A15="Coffee Systems",Pricing_Raw!B15<>"Bosch/Siemens (Own)"),Pricing_Raw!C15,"") -> 621.41 | P13: =IF(AND(Pricing_Raw!A15="Cordless Vacuums",Pricing_Raw!B15<>"Bosch/Siemens (Own)"),Pricing_Raw!C15,"") | Q13: =IF(AND(Pricing_Raw!A15="Dishwashers",Pricing_Raw!B15<>"Bosch/Siemens (Own)"),Pricing_Raw!C15,"") | R13: =IF(AND(Pricing_Raw!A15="Washing Machines",Pricing_Raw!B15<>"Bosch/Siemens (Own)"),Pricing_Raw!C15,"") | S13: =IF(AND(Pricing_Raw!A15="Small Kitchen Appliances",Pricing_Raw!B15<>"Bosch/Siemens (Own)"),Pricing_Raw!C15,"")
N14: =IF(AND(Pricing_Raw!A16="Smart Ovens",Pricing_Raw!B16<>"Bosch/Siemens (Own)"),Pricing_Raw!C16,"") | O14: =IF(AND(Pricing_Raw!A16="Coffee Systems",Pricing_Raw!B16<>"Bosch/Siemens (Own)"),Pricing_Raw!C16,"") -> 576.14 | P14: =IF(AND(Pricing_Raw!A16="Cordless Vacuums",Pricing_Raw!B16<>"Bosch/Siemens (Own)"),Pricing_Raw!C16,"") | Q14: =IF(AND(Pricing_Raw!A16="Dishwashers",Pricing_Raw!B16<>"Bosch/Siemens (Own)"),Pricing_Raw!C16,"") | R14: =IF(AND(Pricing_Raw!A16="Washing Machines",Pricing_Raw!B16<>"Bosch/Siemens (Own)"),Pricing_Raw!C16,"") | S14: =IF(AND(Pricing_Raw!A16="Small Kitchen Appliances",Pricing_Raw!B16<>"Bosch/Siemens (Own)"),Pricing_Raw!C16,"")
N15: =IF(AND(Pricing_Raw!A17="Smart Ovens",Pricing_Raw!B17<>"Bosch/Siemens (Own)"),Pricing_Raw!C17,"") | O15: =IF(AND(Pricing_Raw!A17="Coffee Systems",Pricing_Raw!B17<>"Bosch/Siemens (Own)"),Pricing_Raw!C17,"") -> 495.44 | P15: =IF(AND(Pricing_Raw!A17="Cordless Vacuums",Pricing_Raw!B17<>"Bosch/Siemens (Own)"),Pricing_Raw!C17,"") | Q15: =IF(AND(Pricing_Raw!A17="Dishwashers",Pricing_Raw!B17<>"Bosch/Siemens (Own)"),Pricing_Raw!C17,"") | R15: =IF(AND(Pricing_Raw!A17="Washing Machines",Pricing_Raw!B17<>"Bosch/Siemens (Own)"),Pricing_Raw!C17,"") | S15: =IF(AND(Pricing_Raw!A17="Small Kitchen Appliances",Pricing_Raw!B17<>"Bosch/Siemens (Own)"),Pricing_Raw!C17,"")
B16: 2. Full Competitor Detail (for chart reference) | N16: =IF(AND(Pricing_Raw!A18="Smart Ovens",Pricing_Raw!B18<>"Bosch/Siemens (Own)"),Pricing_Raw!C18,"") | O16: =IF(AND(Pricing_Raw!A18="Coffee Systems",Pricing_Raw!B18<>"Bosch/Siemens (Own)"),Pricing_Raw!C18,"") -> 660.66 | P16: =IF(AND(Pricing_Raw!A18="Cordless Vacuums",Pricing_Raw!B18<>"Bosch/Siemens (Own)"),Pricing_Raw!C18,"") | Q16: =IF(AND(Pricing_Raw!A18="Dishwashers",Pricing_Raw!B18<>"Bosch/Siemens (Own)"),Pricing_Raw!C18,"") | R16: =IF(AND(Pricing_Raw!A18="Washing Machines",Pricing_Raw!B18<>"Bosch/Siemens (Own)"),Pricing_Raw!C18,"") | S16: =IF(AND(Pricing_Raw!A18="Small Kitchen Appliances",Pricing_Raw!B18<>"Bosch/Siemens (Own)"),Pricing_Raw!C18,"")
B17: Product Line | C17: Competitor | D17: List Price (EUR) | E17: Rating (out of 5) | F17: Delivery (Days) | N17: =IF(AND(Pricing_Raw!A19="Smart Ovens",Pricing_Raw!B19<>"Bosch/Siemens (Own)"),Pricing_Raw!C19,"") | O17: =IF(AND(Pricing_Raw!A19="Coffee Systems",Pricing_Raw!B19<>"Bosch/Siemens (Own)"),Pricing_Raw!C19,"") | P17: =IF(AND(Pricing_Raw!A19="Cordless Vacuums",Pricing_Raw!B19<>"Bosch/Siemens (Own)"),Pricing_Raw!C19,"") | Q17: =IF(AND(Pricing_Raw!A19="Dishwashers",Pricing_Raw!B19<>"Bosch/Siemens (Own)"),Pricing_Raw!C19,"") | R17: =IF(AND(Pricing_Raw!A19="Washing Machines",Pricing_Raw!B19<>"Bosch/Siemens (Own)"),Pricing_Raw!C19,"") | S17: =IF(AND(Pricing_Raw!A19="Small Kitchen Appliances",Pricing_Raw!B19<>"Bosch/Siemens (Own)"),Pricing_Raw!C19,"")
B18: =Pricing_Raw!A5 -> Smart Ovens | C18: =Pricing_Raw!B5 -> Bosch/Siemens (Own) | D18: =Pricing_Raw!C5 -> 899 | E18: =Pricing_Raw!D5 -> 3.6 | F18: =Pricing_Raw!E5 -> 7 | N18: =IF(AND(Pricing_Raw!A20="Smart Ovens",Pricing_Raw!B20<>"Bosch/Siemens (Own)"),Pricing_Raw!C20,"") | O18: =IF(AND(Pricing_Raw!A20="Coffee Systems",Pricing_Raw!B20<>"Bosch/Siemens (Own)"),Pricing_Raw!C20,"") | P18: =IF(AND(Pricing_Raw!A20="Cordless Vacuums",Pricing_Raw!B20<>"Bosch/Siemens (Own)"),Pricing_Raw!C20,"") -> 383.87 | Q18: =IF(AND(Pricing_Raw!A20="Dishwashers",Pricing_Raw!B20<>"Bosch/Siemens (Own)"),Pricing_Raw!C20,"") | R18: =IF(AND(Pricing_Raw!A20="Washing Machines",Pricing_Raw!B20<>"Bosch/Siemens (Own)"),Pricing_Raw!C20,"") | S18: =IF(AND(Pricing_Raw!A20="Small Kitchen Appliances",Pricing_Raw!B20<>"Bosch/Siemens (Own)"),Pricing_Raw!C20,"")
B19: =Pricing_Raw!A6 -> Smart Ovens | C19: =Pricing_Raw!B6 -> Miele | D19: =Pricing_Raw!C6 -> 1035.02 | E19: =Pricing_Raw!D6 -> 3.8 | F19: =Pricing_Raw!E6 -> 4 | N19: =IF(AND(Pricing_Raw!A21="Smart Ovens",Pricing_Raw!B21<>"Bosch/Siemens (Own)"),Pricing_Raw!C21,"") | O19: =IF(AND(Pricing_Raw!A21="Coffee Systems",Pricing_Raw!B21<>"Bosch/Siemens (Own)"),Pricing_Raw!C21,"") | P19: =IF(AND(Pricing_Raw!A21="Cordless Vacuums",Pricing_Raw!B21<>"Bosch/Siemens (Own)"),Pricing_Raw!C21,"") -> 321.81 | Q19: =IF(AND(Pricing_Raw!A21="Dishwashers",Pricing_Raw!B21<>"Bosch/Siemens (Own)"),Pricing_Raw!C21,"") | R19: =IF(AND(Pricing_Raw!A21="Washing Machines",Pricing_Raw!B21<>"Bosch/Siemens (Own)"),Pricing_Raw!C21,"") | S19: =IF(AND(Pricing_Raw!A21="Small Kitchen Appliances",Pricing_Raw!B21<>"Bosch/Siemens (Own)"),Pricing_Raw!C21,"")
B20: =Pricing_Raw!A7 -> Smart Ovens | C20: =Pricing_Raw!B7 -> AEG/Electrolux | D20: =Pricing_Raw!C7 -> 1023.74 | E20: =Pricing_Raw!D7 -> 4 | F20: =Pricing_Raw!E7 -> 7 | N20: =IF(AND(Pricing_Raw!A22="Smart Ovens",Pricing_Raw!B22<>"Bosch/Siemens (Own)"),Pricing_Raw!C22,"") | O20: =IF(AND(Pricing_Raw!A22="Coffee Systems",Pricing_Raw!B22<>"Bosch/Siemens (Own)"),Pricing_Raw!C22,"") | P20: =IF(AND(Pricing_Raw!A22="Cordless Vacuums",Pricing_Raw!B22<>"Bosch/Siemens (Own)"),Pricing_Raw!C22,"") -> 439.67 | Q20: =IF(AND(Pricing_Raw!A22="Dishwashers",Pricing_Raw!B22<>"Bosch/Siemens (Own)"),Pricing_Raw!C22,"") | R20: =IF(AND(Pricing_Raw!A22="Washing Machines",Pricing_Raw!B22<>"Bosch/Siemens (Own)"),Pricing_Raw!C22,"") | S20: =IF(AND(Pricing_Raw!A22="Small Kitchen Appliances",Pricing_Raw!B22<>"Bosch/Siemens (Own)"),Pricing_Raw!C22,"")
B21: =Pricing_Raw!A8 -> Smart Ovens | C21: =Pricing_Raw!B8 -> Philips | D21: =Pricing_Raw!C8 -> 941.62 | E21: =Pricing_Raw!D8 -> 4 | F21: =Pricing_Raw!E8 -> 10 | N21: =IF(AND(Pricing_Raw!A23="Smart Ovens",Pricing_Raw!B23<>"Bosch/Siemens (Own)"),Pricing_Raw!C23,"") | O21: =IF(AND(Pricing_Raw!A23="Coffee Systems",Pricing_Raw!B23<>"Bosch/Siemens (Own)"),Pricing_Raw!C23,"") | P21: =IF(AND(Pricing_Raw!A23="Cordless Vacuums",Pricing_Raw!B23<>"Bosch/Siemens (Own)"),Pricing_Raw!C23,"") -> 424.32 | Q21: =IF(AND(Pricing_Raw!A23="Dishwashers",Pricing_Raw!B23<>"Bosch/Siemens (Own)"),Pricing_Raw!C23,"") | R21: =IF(AND(Pricing_Raw!A23="Washing Machines",Pricing_Raw!B23<>"Bosch/Siemens (Own)"),Pricing_Raw!C23,"") | S21: =IF(AND(Pricing_Raw!A23="Small Kitchen Appliances",Pricing_Raw!B23<>"Bosch/Siemens (Own)"),Pricing_Raw!C23,"")
B22: =Pricing_Raw!A9 -> Smart Ovens | C22: =Pricing_Raw!B9 -> Beko | D22: =Pricing_Raw!C9 -> 843.85 | E22: =Pricing_Raw!D9 -> 4.3 | F22: =Pricing_Raw!E9 -> 2 | N22: =IF(AND(Pricing_Raw!A24="Smart Ovens",Pricing_Raw!B24<>"Bosch/Siemens (Own)"),Pricing_Raw!C24,"") | O22: =IF(AND(Pricing_Raw!A24="Coffee Systems",Pricing_Raw!B24<>"Bosch/Siemens (Own)"),Pricing_Raw!C24,"") | P22: =IF(AND(Pricing_Raw!A24="Cordless Vacuums",Pricing_Raw!B24<>"Bosch/Siemens (Own)"),Pricing_Raw!C24,"") -> 466.55 | Q22: =IF(AND(Pricing_Raw!A24="Dishwashers",Pricing_Raw!B24<>"Bosch/Siemens (Own)"),Pricing_Raw!C24,"") | R22: =IF(AND(Pricing_Raw!A24="Washing Machines",Pricing_Raw!B24<>"Bosch/Siemens (Own)"),Pricing_Raw!C24,"") | S22: =IF(AND(Pricing_Raw!A24="Small Kitchen Appliances",Pricing_Raw!B24<>"Bosch/Siemens (Own)"),Pricing_Raw!C24,"")
B23: =Pricing_Raw!A10 -> Smart Ovens | C23: =Pricing_Raw!B10 -> Samsung | D23: =Pricing_Raw!C10 -> 1080.14 | E23: =Pricing_Raw!D10 -> 3.8 | F23: =Pricing_Raw!E10 -> 10 | N23: =IF(AND(Pricing_Raw!A25="Smart Ovens",Pricing_Raw!B25<>"Bosch/Siemens (Own)"),Pricing_Raw!C25,"") | O23: =IF(AND(Pricing_Raw!A25="Coffee Systems",Pricing_Raw!B25<>"Bosch/Siemens (Own)"),Pricing_Raw!C25,"") | P23: =IF(AND(Pricing_Raw!A25="Cordless Vacuums",Pricing_Raw!B25<>"Bosch/Siemens (Own)"),Pricing_Raw!C25,"") -> 341.78 | Q23: =IF(AND(Pricing_Raw!A25="Dishwashers",Pricing_Raw!B25<>"Bosch/Siemens (Own)"),Pricing_Raw!C25,"") | R23: =IF(AND(Pricing_Raw!A25="Washing Machines",Pricing_Raw!B25<>"Bosch/Siemens (Own)"),Pricing_Raw!C25,"") | S23: =IF(AND(Pricing_Raw!A25="Small Kitchen Appliances",Pricing_Raw!B25<>"Bosch/Siemens (Own)"),Pricing_Raw!C25,"")
B24: =Pricing_Raw!A11 -> Smart Ovens | C24: =Pricing_Raw!B11 -> LG | D24: =Pricing_Raw!C11 -> 969.83 | E24: =Pricing_Raw!D11 -> 3.6 | F24: =Pricing_Raw!E11 -> 10 | N24: =IF(AND(Pricing_Raw!A26="Smart Ovens",Pricing_Raw!B26<>"Bosch/Siemens (Own)"),Pricing_Raw!C26,"") | O24: =IF(AND(Pricing_Raw!A26="Coffee Systems",Pricing_Raw!B26<>"Bosch/Siemens (Own)"),Pricing_Raw!C26,"") | P24: =IF(AND(Pricing_Raw!A26="Cordless Vacuums",Pricing_Raw!B26<>"Bosch/Siemens (Own)"),Pricing_Raw!C26,"") | Q24: =IF(AND(Pricing_Raw!A26="Dishwashers",Pricing_Raw!B26<>"Bosch/Siemens (Own)"),Pricing_Raw!C26,"") | R24: =IF(AND(Pricing_Raw!A26="Washing Machines",Pricing_Raw!B26<>"Bosch/Siemens (Own)"),Pricing_Raw!C26,"") | S24: =IF(AND(Pricing_Raw!A26="Small Kitchen Appliances",Pricing_Raw!B26<>"Bosch/Siemens (Own)"),Pricing_Raw!C26,"")
B25: =Pricing_Raw!A12 -> Coffee Systems | C25: =Pricing_Raw!B12 -> Bosch/Siemens (Own) | D25: =Pricing_Raw!C12 -> 549 | E25: =Pricing_Raw!D12 -> 4.6 | F25: =Pricing_Raw!E12 -> 3 | N25: =IF(AND(Pricing_Raw!A27="Smart Ovens",Pricing_Raw!B27<>"Bosch/Siemens (Own)"),Pricing_Raw!C27,"") | O25: =IF(AND(Pricing_Raw!A27="Coffee Systems",Pricing_Raw!B27<>"Bosch/Siemens (Own)"),Pricing_Raw!C27,"") | P25: =IF(AND(Pricing_Raw!A27="Cordless Vacuums",Pricing_Raw!B27<>"Bosch/Siemens (Own)"),Pricing_Raw!C27,"") | Q25: =IF(AND(Pricing_Raw!A27="Dishwashers",Pricing_Raw!B27<>"Bosch/Siemens (Own)"),Pricing_Raw!C27,"") -> 927.08 | R25: =IF(AND(Pricing_Raw!A27="Washing Machines",Pricing_Raw!B27<>"Bosch/Siemens (Own)"),Pricing_Raw!C27,"") | S25: =IF(AND(Pricing_Raw!A27="Small Kitchen Appliances",Pricing_Raw!B27<>"Bosch/Siemens (Own)"),Pricing_Raw!C27,"")
B26: =Pricing_Raw!A13 -> Coffee Systems | C26: =Pricing_Raw!B13 -> Miele | D26: =Pricing_Raw!C13 -> 616.53 | E26: =Pricing_Raw!D13 -> 4.7 | F26: =Pricing_Raw!E13 -> 2 | N26: =IF(AND(Pricing_Raw!A28="Smart Ovens",Pricing_Raw!B28<>"Bosch/Siemens (Own)"),Pricing_Raw!C28,"") | O26: =IF(AND(Pricing_Raw!A28="Coffee Systems",Pricing_Raw!B28<>"Bosch/Siemens (Own)"),Pricing_Raw!C28,"") | P26: =IF(AND(Pricing_Raw!A28="Cordless Vacuums",Pricing_Raw!B28<>"Bosch/Siemens (Own)"),Pricing_Raw!C28,"") | Q26: =IF(AND(Pricing_Raw!A28="Dishwashers",Pricing_Raw!B28<>"Bosch/Siemens (Own)"),Pricing_Raw!C28,"") -> 737.9 | R26: =IF(AND(Pricing_Raw!A28="Washing Machines",Pricing_Raw!B28<>"Bosch/Siemens (Own)"),Pricing_Raw!C28,"") | S26: =IF(AND(Pricing_Raw!A28="Small Kitchen Appliances",Pricing_Raw!B28<>"Bosch/Siemens (Own)"),Pricing_Raw!C28,"")
B27: =Pricing_Raw!A14 -> Coffee Systems | C27: =Pricing_Raw!B14 -> AEG/Electrolux | D27: =Pricing_Raw!C14 -> 672.51 | E27: =Pricing_Raw!D14 -> 4.3 | F27: =Pricing_Raw!E14 -> 4 | N27: =IF(AND(Pricing_Raw!A29="Smart Ovens",Pricing_Raw!B29<>"Bosch/Siemens (Own)"),Pricing_Raw!C29,"") | O27: =IF(AND(Pricing_Raw!A29="Coffee Systems",Pricing_Raw!B29<>"Bosch/Siemens (Own)"),Pricing_Raw!C29,"") | P27: =IF(AND(Pricing_Raw!A29="Cordless Vacuums",Pricing_Raw!B29<>"Bosch/Siemens (Own)"),Pricing_Raw!C29,"") | Q27: =IF(AND(Pricing_Raw!A29="Dishwashers",Pricing_Raw!B29<>"Bosch/Siemens (Own)"),Pricing_Raw!C29,"") -> 809.75 | R27: =IF(AND(Pricing_Raw!A29="Washing Machines",Pricing_Raw!B29<>"Bosch/Siemens (Own)"),Pricing_Raw!C29,"") | S27: =IF(AND(Pricing_Raw!A29="Small Kitchen Appliances",Pricing_Raw!B29<>"Bosch/Siemens (Own)"),Pricing_Raw!C29,"")
B28: =Pricing_Raw!A15 -> Coffee Systems | C28: =Pricing_Raw!B15 -> Philips | D28: =Pricing_Raw!C15 -> 621.41 | E28: =Pricing_Raw!D15 -> 4.8 | F28: =Pricing_Raw!E15 -> 3 | N28: =IF(AND(Pricing_Raw!A30="Smart Ovens",Pricing_Raw!B30<>"Bosch/Siemens (Own)"),Pricing_Raw!C30,"") | O28: =IF(AND(Pricing_Raw!A30="Coffee Systems",Pricing_Raw!B30<>"Bosch/Siemens (Own)"),Pricing_Raw!C30,"") | P28: =IF(AND(Pricing_Raw!A30="Cordless Vacuums",Pricing_Raw!B30<>"Bosch/Siemens (Own)"),Pricing_Raw!C30,"") | Q28: =IF(AND(Pricing_Raw!A30="Dishwashers",Pricing_Raw!B30<>"Bosch/Siemens (Own)"),Pricing_Raw!C30,"") -> 665.71 | R28: =IF(AND(Pricing_Raw!A30="Washing Machines",Pricing_Raw!B30<>"Bosch/Siemens (Own)"),Pricing_Raw!C30,"") | S28: =IF(AND(Pricing_Raw!A30="Small Kitchen Appliances",Pricing_Raw!B30<>"Bosch/Siemens (Own)"),Pricing_Raw!C30,"")
B29: =Pricing_Raw!A16 -> Coffee Systems | C29: =Pricing_Raw!B16 -> Beko | D29: =Pricing_Raw!C16 -> 576.14 | E29: =Pricing_Raw!D16 -> 3.8 | F29: =Pricing_Raw!E16 -> 3 | N29: =IF(AND(Pricing_Raw!A31="Smart Ovens",Pricing_Raw!B31<>"Bosch/Siemens (Own)"),Pricing_Raw!C31,"") | O29: =IF(AND(Pricing_Raw!A31="Coffee Systems",Pricing_Raw!B31<>"Bosch/Siemens (Own)"),Pricing_Raw!C31,"") | P29: =IF(AND(Pricing_Raw!A31="Cordless Vacuums",Pricing_Raw!B31<>"Bosch/Siemens (Own)"),Pricing_Raw!C31,"") | Q29: =IF(AND(Pricing_Raw!A31="Dishwashers",Pricing_Raw!B31<>"Bosch/Siemens (Own)"),Pricing_Raw!C31,"") -> 617.03 | R29: =IF(AND(Pricing_Raw!A31="Washing Machines",Pricing_Raw!B31<>"Bosch/Siemens (Own)"),Pricing_Raw!C31,"") | S29: =IF(AND(Pricing_Raw!A31="Small Kitchen Appliances",Pricing_Raw!B31<>"Bosch/Siemens (Own)"),Pricing_Raw!C31,"")
... B44: =Pricing_Raw!A31 -> Dishwashers | C44: =Pricing_Raw!B31 -> Samsung | D44: =Pricing_Raw!C31 -> 617.03 | E44: =Pricing_Raw!D31 -> 4.7 | F44: =Pricing_Raw!E31 -> 7 | N44: =IF(AND(Pricing_Raw!A46="Smart Ovens",Pricing_Raw!B46<>"Bosch/Siemens (Own)"),Pricing_Raw!C46,"") | O44: =IF(AND(Pricing_Raw!A46="Coffee Systems",Pricing_Raw!B46<>"Bosch/Siemens (Own)"),Pricing_Raw!C46,"") | P44: =IF(AND(Pricing_Raw!A46="Cordless Vacuums",Pricing_Raw!B46<>"Bosch/Siemens (Own)"),Pricing_Raw!C46,"") | Q44: =IF(AND(Pricing_Raw!A46="Dishwashers",Pricing_Raw!B46<>"Bosch/Siemens (Own)"),Pricing_Raw!C46,"") | R44: =IF(AND(Pricing_Raw!A46="Washing Machines",Pricing_Raw!B46<>"Bosch/Siemens (Own)"),Pricing_Raw!C46,"") | S44: =IF(AND(Pricing_Raw!A46="Small Kitchen Appliances",Pricing_Raw!B46<>"Bosch/Siemens (Own)"),Pricing_Raw!C46,"") -> 159.67
B45: =Pricing_Raw!A32 -> Dishwashers | C45: =Pricing_Raw!B32 -> LG | D45: =Pricing_Raw!C32 -> 760.86 | E45: =Pricing_Raw!D32 -> 4.4 | F45: =Pricing_Raw!E32 -> 7
B46: =Pricing_Raw!A33 -> Washing Machines | C46: =Pricing_Raw!B33 -> Bosch/Siemens (Own) | D46: =Pricing_Raw!C33 -> 699 | E46: =Pricing_Raw!D33 -> 3.9 | F46: =Pricing_Raw!E33 -> 3
B47: =Pricing_Raw!A34 -> Washing Machines | C47: =Pricing_Raw!B34 -> Miele | D47: =Pricing_Raw!C34 -> 662.26 | E47: =Pricing_Raw!D34 -> 3.9 | F47: =Pricing_Raw!E34 -> 2
B48: =Pricing_Raw!A35 -> Washing Machines | C48: =Pricing_Raw!B35 -> AEG/Electrolux | D48: =Pricing_Raw!C35 -> 624.61 | E48: =Pricing_Raw!D35 -> 3.7 | F48: =Pricing_Raw!E35 -> 3
B49: =Pricing_Raw!A36 -> Washing Machines | C49: =Pricing_Raw!B36 -> Philips | D49: =Pricing_Raw!C36 -> 660.9 | E49: =Pricing_Raw!D36 -> 4.4 | F49: =Pricing_Raw!E36 -> 4
B50: =Pricing_Raw!A37 -> Washing Machines | C50: =Pricing_Raw!B37 -> Beko | D50: =Pricing_Raw!C37 -> 851.88 | E50: =Pricing_Raw!D37 -> 3.9 | F50: =Pricing_Raw!E37 -> 2
B51: =Pricing_Raw!A38 -> Washing Machines | C51: =Pricing_Raw!B38 -> Samsung | D51: =Pricing_Raw!C38 -> 766.27 | E51: =Pricing_Raw!D38 -> 3.9 | F51: =Pricing_Raw!E38 -> 3
B52: =Pricing_Raw!A39 -> Washing Machines | C52: =Pricing_Raw!B39 -> LG | D52: =Pricing_Raw!C39 -> 733.86 | E52: =Pricing_Raw!D39 -> 3.6 | F52: =Pricing_Raw!E39 -> 4
B53: =Pricing_Raw!A40 -> Small Kitchen Appliances | C53: =Pricing_Raw!B40 -> Bosch/Siemens (Own) | D53: =Pricing_Raw!C40 -> 129 | E53: =Pricing_Raw!D40 -> 4.4 | F53: =Pricing_Raw!E40 -> 4
B54: =Pricing_Raw!A41 -> Small Kitchen Appliances | C54: =Pricing_Raw!B41 -> Miele | D54: =Pricing_Raw!C41 -> 123.78 | E54: =Pricing_Raw!D41 -> 4.7 | F54: =Pricing_Raw!E41 -> 7
B55: =Pricing_Raw!A42 -> Small Kitchen Appliances | C55: =Pricing_Raw!B42 -> AEG/Electrolux | D55: =Pricing_Raw!C42 -> 120.43 | E55: =Pricing_Raw!D42 -> 3.8 | F55: =Pricing_Raw!E42 -> 7
...

Sheet Executive_Dashboard
B2: D2C Sales Performance — Executive Dashboard
B3: Live view for management and sales leadership | Source: CRM_Clean, Competitor_Benchmark
B5: Total Pipeline Value | F5: Closed Won Revenue | J5: Overall Win Rate | N5: Avg Deal Size (Won)
B6: =Pipeline_Analysis!D12 -> 709214.33 | F6: =SUMIFS(CRM_Clean!K5:K854,CRM_Clean!H5:H854,"Closed Won") -> 242160.98 | J6: =SUM(CRM_Clean!M5:M854)/(COUNTIF(CRM_Clean!H5:H854,"Closed Won")+COUNTIF(CRM_Clean!H5:H854,"Closed Lost")) -> 0.58269231 | N6: =AVERAGEIFS(CRM_Clean!K5:K854,CRM_Clean!H5:H854,"Closed Won") -> 799.21115
B9: Pipeline by Stage
B27: Revenue Mix & Pricing
B45: Lead Source Effectiveness
